Workbook

Sheet datos_limpios
A1: fecha_hora_cest | B1: marca_temp_CEST | C1: id_comercio | D1: link | E1: sector_bm | F1: Calle | G1: Altura | H1: direccion | I1: ID_direcciones | J1: Rubro | K1: leche | L1: harina | M1: azucar | N1: arroz | O1: papa | P1: fiambre/jc | Q1: carne pic | R1: ¿Cuáles son los principales factores que encarecen los productos que vendés? | S1: Inquilino/ Propietario | T1: Alquiler | U1: Dificultades para abastecerse, otros comentarios | V1: cadena | W1: relevado | X1: tanda | Y1: geometry | Z1: numero real
A2: 45818.953 | B2: 0.95277778 | C2: csp_0001 | D2: https://maps.google.com/maps?q=-34.59994888305664%2C-58.37699508666992&z=17&hl=es | J2: Supermercado Carrefour Express | K2: 1485 | L2: 749 | M2: 1050 | N2: 1690 | O2: 1490 | P2: 1790 | V2: si | W2: si | X2: 1 | Y2: POINT(-58.376946823984355 -34.599772246759564)
A3: 45818.955 | B3: 0.95486111 | C3: csp_0002 | D3: https://maps.google.com/maps?q=-34.59996032714844%2C-58.37679672241211&z=17&hl=es | J3: Carniceria RES | Q3: 5450 | V3: si | W3: si | X3: 1 | Y3: POINT(-58.37675915281983 -34.599783646783784)
A4: 45818.956 | B4: 0.95625 | C4: csp_0003 | D4: https://maps.google.com/maps?q=-34.599769592285156%2C-58.376834869384766&z=17&hl=es | J4: Almacen | N4: 1800 | O4: 750 | P4: 1500 | V4: no | W4: si | X4: 1 | Y4: POINT(-58.376872454668245 -34.59954878967517)
A5: 45818.958 | B5: 0.95833333 | C5: csp_0004 | D5: https://maps.google.com/maps?q=-34.598236083984375%2C-58.376956939697266&z=17&hl=es | J5: Almacen Chino | K5: 1300 | L5: 800 | M5: 900 | N5: 1400 | P5: 1200 | V5: no | W5: si | X5: 1 | Y5: POINT(-58.37690862398452 -34.59804178011319)
A6: 45818.96 | B6: 0.96041667 | C6: csp_0005 | D6: https://maps.google.com/maps?q=-34.59791946411133%2C-58.37689971923828&z=17&hl=es | J6: Carniceria Fiambreria | P6: 1950 | V6: si | W6: si | X6: 1 | Y6: POINT(-58.37691579699724 -34.597707516297156)
A7: 45818.961 | B7: 0.96111111 | C7: csp_0006 | D7: https://maps.google.com/maps?q=-34.59733581542969%2C-58.37691879272461&z=17&hl=es | J7: Supermercado Carrefour Express | K7: 1290 | L7: 749 | M7: 949 | N7: 1400 | O7: 1490 | P7: 1790 | V7: si | W7: si | X7: 1 | Y7: POINT(-58.37692416816192 -34.59711498320661)
A8: 45818.966 | B8: 0.96597222 | C8: csp_0007 | D8: https://maps.google.com/maps?q=-34.596309661865234%2C-58.37836837768555&z=17&hl=es | J8: Carniceria RES | Q8: 5450 | V8: si | W8: si | X8: 1 | Y8: POINT(-58.37833085282006 -34.59612420731531)
A9: 45818.967 | B9: 0.96666667 | C9: csp_0008 | D9: https://maps.google.com/maps?q=-34.59626770019531%2C-58.37843322753906&z=17&hl=es | J9: Almacen | K9: 2400 | L9: 1300 | M9: 1600 | N9: 2400 | P9: 1700 | V9: no | W9: si | X9: 1 | Y9: POINT(-58.37836346631361 -34.59609103893263)
A10: 45818.968 | B10: 0.96805556 | C10: csp_0009 | D10: https://maps.google.com/maps?q=-34.59589767456055%2C-58.37848663330078&z=17&hl=es | J10: Supermercado Carrefour Express | K10: 1290 | L10: 749 | M10: 899 | N10: 1290 | O10: 1490 | P10: 1785 | V10: si | W10: si | X10: 1 | Y10: POINT(-58.37839540864261 -34.59571220639564)
A11: 45818.974 | B11: 0.97430556 | C11: csp_0010 | D11: https://maps.google.com/maps?q=-34.5966682434082%2C-58.37837600708008&z=17&hl=es | J11: Almacen Chino | K11: 1800 | L11: 1500 | M11: 1300 | N11: 1000 | P11: 1000 | V11: no | W11: si | X11: 1 | Y11: POINT(-58.378327723984455 -34.596403223057045)
A12: 45818.976 | B12: 0.97638889 | C12: csp_0011 | D12: https://maps.google.com/maps?q=-34.59672546386719%2C-58.37849044799805&z=17&hl=es | J12: Verduleria | O12: 1000 | V12: no | W12: si | X12: 1 | Y12: POINT(-58.37844212398452 -34.59655767156747)
A13: 45818.978 | B13: 0.97777778 | C13: csp_0012 | D13: https://www.google.com/maps/place/34%C2%B035'50.5%22S+58%C2%B022'44.1%22W/@-34.5975982,-58.3788232,21z/data=!4m4!3m3!8m2!3d-34.5973587!4d-58.3789177?hl=es&entry=ttu&g_ep=EgoyMDI2MDMxMS4wIKXMDSoASAFQAw%3D%3D | J13: Almacen | L13: 1800 | M13: 2000 | P13: 1300 | V13: no | W13: si | X13: 1 | Y13: POINT(-58.37869881477214 -34.5976081096709)
A14: 45818.978 | B14: 0.97847222 | C14: csp_0013 | D14: https://maps.google.com/maps?q=-34.59750747680664%2C-58.3781852722168&z=17&hl=es | J14: Supermercado Dia | K14: 1740 | L14: 790 | M14: 990 | N14: 1190 | P14: 2410 | V14: si | W14: si | X14: 1 | Y14: POINT(-58.378201396997426 -34.597295515245946)
A15: 45818.981 | B15: 0.98125 | C15: csp_0014 | D15: https://maps.google.com/maps?q=-34.59797668457031%2C-58.378299713134766&z=17&hl=es | J15: Almacen | N15: 1800 | O15: 1000 | V15: no | W15: si | X15: 1 | Y15: POINT(-58.378272881655505 -34.59776471644315)
A16: 45818.983 | B16: 0.98263889 | C16: csp_0015 | D16: https://maps.google.com/maps?q=-34.598628997802734%2C-58.37840270996094&z=17&hl=es | J16: Supermercado Carrefour Express | K16: 1290 | L16: 749 | M16: 899 | N16: 1290 | O16: 1490 | P16: 1785 | V16: si | W16: si | X16: 1 | Y16: POINT(-58.3784617123392 -34.59848766978374)
A17: 45818.986 | B17: 0.98611111 | C17: csp_0016 | D17: https://maps.google.com/maps?q=-34.60411071777344%2C-58.3782844543457&z=17&hl=es | J17: Almacen | K17: 1900 | L17: 1300 | M17: 1400 | N17: 2600 | P17: 1035 | V17: no | W17: si | X17: 1 | Y17: POINT(-58.37825768165517 -34.603881070332164)
A18: 45818.99 | B18: 0.99027778 | C18: csp_0017 | D18: https://maps.google.com/maps?q=-34.60270690917969%2C-58.37809371948242&z=17&hl=es | J18: Fiambreria | N18: 2200 | O18: 900 | P18: 1742 | V18: no | W18: si | X18: 1 | Y18: POINT(-58.37807761049078 -34.60250375954193)
A19: 45818.991 | B19: 0.99097222 | C19: csp_0018 | D19: https://maps.google.com/maps?q=-34.60324478149414%2C-58.3781623840332&z=17&hl=es | J19: Supermercado Carrefour Express | K19: 1290 | L19: 749 | M19: 899 | N19: 1290 | O19: 1490 | P19: 1785 | V19: si | W19: si | X19: 1 | Y19: POINT(-58.378135581655215 -34.60302399891231)
A20: 45818.997 | B20: 0.99652778 | C20: csp_0019 | D20: https://maps.google.com/maps?q=-34.601531982421875%2C-58.37953186035156&z=17&hl=es | J20: Almacen Chino | K20: 1700 | L20: 900 | M20: 1300 | N20: 1200 | O20: 1000 | P20: 1600 | Q20: 8600 | V20: no | W20: si | X20: 1 | Y20: POINT(-58.379472895148915 -34.60132885666888)
A21: 45818.999 | B21: 0.99930556 | C21: csp_0020 | D21: https://maps.google.com/maps?q=-34.599891662597656%2C-58.37984848022461&z=17&hl=es | J21: Verduleria | O21: 1000 | V21: no | W21: si | X21: 1 | Y21: POINT(-58.37983241049086 -34.599679721329295)
A22: 45819 | B22: 0 | C22: csp_0021 | D22: https://maps.google.com/maps?q=-34.599876403808594%2C-58.379634857177734&z=17&hl=es | J22: Supermercado Dia | K22: 1390 | L22: 790 | M22: 990 | N22: 1600 | P22: 2145 | V22: si | W22: si | X22: 1 | Y22: POINT(-58.379683183503644 -34.599664421290306)
A23: 45819.003 | B23: 0.0027777778 | C23: csp_0022 | D23: https://maps.google.com/maps?q=-34.59871292114258%2C-58.37973403930664&z=17&hl=es | J23: Almacen | M23: 1500 | N23: 1800 | V23: no | W23: si | X23: 1 | Y23: POINT(-58.37975009699739 -34.59856273847909)
A24: 45819.003 | B24: 0.0034722222 | C24: csp_0023 | D24: https://maps.google.com/maps?q=-34.5986896%2C-58.3797565&z=17&hl=es | J24: Verduleria | O24: 800 | V24: no | W24: si | X24: 1 | Y24: POINT(-58.379740410490925 -34.59846878680459)
A25: 45819.005 | B25: 0.0048611111 | C25: csp_0024 | D25: https://maps.google.com/maps?q=-34.598295%2C-58.3797894&z=17&hl=es | J25: Almacen | L25: 2500 | N25: 2000 | V25: no | W25: si | X25: 1 | Y25: POINT(-58.379773310490876 -34.59810951174743)
A26: 45819.006 | B26: 0.0055555556 | C26: csp_0025 | D26: https://maps.google.com/maps?q=-34.5980989%2C-58.3797356&z=17&hl=es | J26: Almacen | M26: 1100 | N26: 1800 | O26: 700 | P26: 1200 | Q26: 14500 | V26: no | W26: si | X26: 1 | Y26: POINT(-58.3797624258329 -34.59795756888206)
A27: 45819.009 | B27: 0.0090277778 | C27: csp_0026 | D27: https://maps.google.com/maps?q=-34.5971262%2C-58.3798431&z=17&hl=es | J27: Almacen Chino | L27: 1500 | M27: 1700 | N27: 2000 | O27: 1200 | P27: 1500 | Q27: 900 | V27: no | W27: si | X27: 1 | Y27: POINT(-58.379805552819946 -34.59694954075799)
A28: 45820.735 | B28: 0.73541667 | C28: csp_0027 | D28: https://maps.google.com/maps?q=-34.59231185913086%2C-58.37621307373047&z=17&hl=es | J28: Almacen Chino | K28: 1600 | L28: 1000 | M28: 1500 | N28: 1800 | O28: 1000 | P28: 2300 | V28: no | W28: si | X28: 1 | Y28: POINT(-58.376207739326574 -34.592117566258686)
A29: 45820.746 | B29: 0.74583333 | C29: csp_0028 | D29: https://maps.google.com/maps?q=-34.58771896362305%2C-58.38430404663086&z=17&hl=es | J29: Almacen Chino | K29: 1400 | L29: 2000 | M29: 2000 | N29: 4000 | P29: 2136 | V29: no | W29: si | X29: 1 | Y29: POINT(-58.384298639326836 -34.587533488139755)
A30: 45820.751 | B30: 0.75069444 | C30: csp_0029 | D30: https://maps.google.com/maps?q=-34.586002349853516%2C-58.387351989746094&z=17&hl=es | J30: Verduleria | O30: 1333 | V30: no | W30: si | X30: 1 | Y30: POINT(-58.38738955466894 -34.58580795150509)
A31: 45820.751 | B31: 0.75138889 | C31: csp_0030 | D31: https://maps.google.com/maps?q=-34.585933685302734%2C-58.387969970703125&z=17&hl=es | J31: Supermercado Carrefour Express | K31: 1290 | L31: 749 | M31: 949 | N31: 1290 | O31: 1400 | P31: 1788 | Q31: 9350 | V31: si | W31: si | X31: 1 | Y31: POINT(-58.38795391049146 -34.585721685720785)
A32: 45820.76 | B32: 0.75972222 | C32: csp_0031 | D32: https://maps.google.com/maps?q=-34.5875244140625%2C-58.38737106323242&z=17&hl=es | J32: Kiosco Mini Market | K32: 2100 | L32: 1200 | M32: 2000 | N32: 5200 | U32: (U marca de cada producto, y pocos ejemplares por producto. muy poco provisto) | V32: no | W32: si | X32: 1 | Y32: POINT(-58.38743011233964 -34.58733888770553)
A33: 45820.77 | B33: 0.77013889 | C33: csp_0032 | D33: https://www.google.com/maps/@-34.5917245,-58.3792782,21z?hl=es&entry=ttu&g_ep=EgoyMDI2MDMxMS4wIKXMDSoASAFQAw%3D%3D | J33: Almacen | K33: 1485 | L33: 940 | M33: 949 | N33: 1400 | O33: 1400 | P33: 1288 | V33: no | W33: si | X33: 1 | Y33: POINT(-58.37935967209949 -34.59165991469645)
A34: 45820.774 | B34: 0.77361111 | C34: csp_0033 | D34: https://maps.google.com/maps?q=-34.59185791015625%2C-58.378448486328125&z=17&hl=es | J34: Supermercado Disco | K34: 1290 | L34: 870 | M34: 1080 | N34: 1050 | O34: 1629 | P34: 1845 | Q34: 5315 | V34: si | W34: si | X34: 1 | Y34: POINT(-58.3784753258331 -34.59167239737799)
A35: 45820.781 | B35: 0.78125 | C35: csp_0034 | D35: https://www.google.com/maps/@-34.5928267,-58.3763974,21z?hl=es&entry=ttu&g_ep=EgoyMDI2MDMxMS4wIKXMDSoASAFQAw%3D%3D | J35: Almacen | L35: 1000 | N35: 1400 | O35: 1500 | V35: no | W35: si | X35: 1 | Y35: POINT(-58.376197216356985 -34.5928172847864)
A36: 45820.787 | B36: 0.78680556 | C36: csp_0035 | D36: https://www.google.com/maps/@-34.5940337,-58.3793313,21z?hl=es&entry=ttu&g_ep=EgoyMDI2MDMxMS4wIKXMDSoASAFQAw%3D%3D | J36: Supermercado Jumbo | K36: 1950 | L36: 870 | M36: 1080 | N36: 1550 | O36: 969 | P36: 139 | Q36: 8855 | V36: si | W36: si | X36: 1 | Y36: POINT(-58.37937322983343 -34.5941396898721)
A37: 45820.792 | B37: 0.79236111 | C37: csp_0036 | D37: https://www.google.com/maps?q=-34.594242095947266,-58.38105392456055&z=17&hl=es | J37: Supermercado Carrefour Express | K37: 1290 | L37: 749 | M37: 949 | N37: 1290 | O37: 1590 | P37: 1788 | V37: si | W37: si | X37: 1 | Y37: POINT(-58.38104853932667 -34.59403893884416)
A38: 45820.795 | B38: 0.79513889 | C38: csp_0037 | D38: https://www.google.com/maps?q=-34.5941162109375,-58.37980270385742&z=17&hl=es | J38: Verduleria | O38: 1000 | V38: no | W38: si | X38: 1 | Y38: POINT(-58.37982952583306 -34.59393953435863)
A39: 45820.796 | B39: 0.79583333 | C39: csp_0038 | D39: https://www.google.com/maps?q=-34.59412384033203,-58.37968444824219&z=17&hl=es | J39: Carniceria RES | Q39: 545 | V39: si | W39: si | X39: 1 | Y39: POINT(-58.37971122583305 -34.59394713437477)
A40: 45820.797 | B40: 0.79722222 | C40: csp_0039 | D40: https://www.google.com/maps?q=-34.594486236572266,-58.381168365478516&z=17&hl=es | J40: Fiambreria | L40: 1400 | M40: 1200 | P40: 1500 | V40: no | W40: si | X40: 1 | Y40: POINT(-58.381227412339314 -34.59430070324479)
...

Sheet limpieza_datos
A1: fecha_hora_cest | B1: marca_temp_CEST | C1: id_comercio | D1: link | E1: sector_bm | F1: Calle | G1: Altura | H1: direccion | I1: ID_direcciones | J1: Rubro | K1: leche | L1: harina | M1: azucar | N1: arroz | O1: papa | P1: fiambre/jc | Q1: carne pic | R1: ¿Cuáles son los principales factores que encarecen los productos que vendés? | S1: Inquilino/ Propietario | T1: Alquiler | U1: Dificultades para abastecerse, otros comentarios | V1: cadena | W1: relevado | X1: tanda | Y1: geometry | Z1: numero real
A2: 45818.953 | B2: 0.95277778 | C2: csp_0001 | D2: https://maps.google.com/maps?q=-34.59994888305664%2C-58.37699508666992&z=17&hl=es | J2: Supermercado Carrefour Express | K2: 1485 | L2: 749 | M2: 1050 | N2: 1690 | O2: 1490 | P2: 1790 | V2: si | W2: si | X2: 1 | Y2: POINT(-58.376946823984355 -34.599772246759564)
A3: 45818.955 | B3: 0.95486111 | C3: csp_0002 | D3: https://maps.google.com/maps?q=-34.59996032714844%2C-58.37679672241211&z=17&hl=es | J3: Carniceria RES | Q3: 5450 | V3: si | W3: si | X3: 1 | Y3: POINT(-58.37675915281983 -34.599783646783784)
A4: 45818.956 | B4: 0.95625 | C4: csp_0003 | D4: https://maps.google.com/maps?q=-34.599769592285156%2C-58.376834869384766&z=17&hl=es | J4: Almacen | N4: 1800 | O4: 750 | P4: 1500 | V4: no | W4: si | X4: 1 | Y4: POINT(-58.376872454668245 -34.59954878967517)
A5: 45818.958 | B5: 0.95833333 | C5: csp_0004 | D5: https://maps.google.com/maps?q=-34.598236083984375%2C-58.376956939697266&z=17&hl=es | J5: Almacen Chino | K5: 1300 | L5: 800 | M5: 900 | N5: 1400 | P5: 1200 | V5: no | W5: si | X5: 1 | Y5: POINT(-58.37690862398452 -34.59804178011319)
A6: 45818.96 | B6: 0.96041667 | C6: csp_0005 | D6: https://maps.google.com/maps?q=-34.59791946411133%2C-58.37689971923828&z=17&hl=es | J6: Carniceria Fiambreria | P6: 1950 | V6: si | W6: si | X6: 1 | Y6: POINT(-58.37691579699724 -34.597707516297156)
A7: 45818.961 | B7: 0.96111111 | C7: csp_0006 | D7: https://maps.google.com/maps?q=-34.59733581542969%2C-58.37691879272461&z=17&hl=es | J7: Supermercado Carrefour Express | K7: 1290 | L7: 749 | M7: 949 | N7: 1400 | O7: 1490 | P7: 1790 | V7: si | W7: si | X7: 1 | Y7: POINT(-58.37692416816192 -34.59711498320661)
A8: 45818.966 | B8: 0.96597222 | C8: csp_0007 | D8: https://maps.google.com/maps?q=-34.596309661865234%2C-58.37836837768555&z=17&hl=es | J8: Carniceria RES | Q8: 5450 | V8: si | W8: si | X8: 1 | Y8: POINT(-58.37833085282006 -34.59612420731531)
A9: 45818.967 | B9: 0.96666667 | C9: csp_0008 | D9: https://maps.google.com/maps?q=-34.59626770019531%2C-58.37843322753906&z=17&hl=es | J9: Almacen | K9: 2400 | L9: 1300 | M9: 1600 | N9: 2400 | P9: 1700 | V9: no | W9: si | X9: 1 | Y9: POINT(-58.37836346631361 -34.59609103893263)
A10: 45818.968 | B10: 0.96805556 | C10: csp_0009 | D10: https://maps.google.com/maps?q=-34.59589767456055%2C-58.37848663330078&z=17&hl=es | J10: Supermercado Carrefour Express | K10: 1290 | L10: 749 | M10: 899 | N10: 1290 | O10: 1490 | P10: 1785 | V10: si | W10: si | X10: 1 | Y10: POINT(-58.37839540864261 -34.59571220639564)
A11: 45818.974 | B11: 0.97430556 | C11: csp_0010 | D11: https://maps.google.com/maps?q=-34.5966682434082%2C-58.37837600708008&z=17&hl=es | J11: Almacen Chino | K11: 1800 | L11: 1500 | M11: 1300 | N11: 1000 | P11: 1000 | V11: no | W11: si | X11: 1 | Y11: POINT(-58.378327723984455 -34.596403223057045)
A12: 45818.976 | B12: 0.97638889 | C12: csp_0011 | D12: https://maps.google.com/maps?q=-34.59672546386719%2C-58.37849044799805&z=17&hl=es | J12: Verduleria | O12: 1000 | V12: no | W12: si | X12: 1 | Y12: POINT(-58.37844212398452 -34.59655767156747)
A13: 45818.978 | B13: 0.97777778 | C13: csp_0012 | D13: https://www.google.com/maps/place/34%C2%B035'50.5%22S+58%C2%B022'44.1%22W/@-34.5975982,-58.3788232,21z/data=!4m4!3m3!8m2!3d-34.5973587!4d-58.3789177?hl=es&entry=ttu&g_ep=EgoyMDI2MDMxMS4wIKXMDSoASAFQAw%3D%3D | J13: Almacen | L13: 1800 | M13: 2000 | P13: 1300 | V13: no | W13: si | X13: 1 | Y13: POINT(-58.37869881477214 -34.5976081096709)
A14: 45818.978 | B14: 0.97847222 | C14: csp_0013 | D14: https://maps.google.com/maps?q=-34.59750747680664%2C-58.3781852722168&z=17&hl=es | J14: Supermercado Dia | K14: 1740 | L14: 790 | M14: 990 | N14: 1190 | P14: 2410 | V14: si | W14: si | X14: 1 | Y14: POINT(-58.378201396997426 -34.597295515245946)
A15: 45818.981 | B15: 0.98125 | C15: csp_0014 | D15: https://maps.google.com/maps?q=-34.59797668457031%2C-58.378299713134766&z=17&hl=es | J15: Almacen | N15: 1800 | O15: 1000 | V15: no | W15: si | X15: 1 | Y15: POINT(-58.378272881655505 -34.59776471644315)
A16: 45818.983 | B16: 0.98263889 | C16: csp_0015 | D16: https://maps.google.com/maps?q=-34.598628997802734%2C-58.37840270996094&z=17&hl=es | J16: Supermercado Carrefour Express | K16: 1290 | L16: 749 | M16: 899 | N16: 1290 | O16: 1490 | P16: 1785 | V16: si | W16: si | X16: 1 | Y16: POINT(-58.3784617123392 -34.59848766978374)
A17: 45818.986 | B17: 0.98611111 | C17: csp_0016 | D17: https://maps.google.com/maps?q=-34.60411071777344%2C-58.3782844543457&z=17&hl=es | J17: Almacen | K17: 1900 | L17: 1300 | M17: 1400 | N17: 2600 | P17: 1035 | V17: no | W17: si | X17: 1 | Y17: POINT(-58.37825768165517 -34.603881070332164)
A18: 45818.99 | B18: 0.99027778 | C18: csp_0017 | D18: https://maps.google.com/maps?q=-34.60270690917969%2C-58.37809371948242&z=17&hl=es | J18: Fiambreria | N18: 2200 | O18: 900 | P18: 1742 | V18: no | W18: si | X18: 1 | Y18: POINT(-58.37807761049078 -34.60250375954193)
A19: 45818.991 | B19: 0.99097222 | C19: csp_0018 | D19: https://maps.google.com/maps?q=-34.60324478149414%2C-58.3781623840332&z=17&hl=es | J19: Supermercado Carrefour Express | K19: 1290 | L19: 749 | M19: 899 | N19: 1290 | O19: 1490 | P19: 1785 | V19: si | W19: si | X19: 1 | Y19: POINT(-58.378135581655215 -34.60302399891231)
A20: 45818.997 | B20: 0.99652778 | C20: csp_0019 | D20: https://maps.google.com/maps?q=-34.601531982421875%2C-58.37953186035156&z=17&hl=es | J20: Almacen Chino | K20: 1700 | L20: 900 | M20: 1300 | N20: 1200 | O20: 1000 | P20: 1600 | Q20: 8600 | V20: no | W20: si | X20: 1 | Y20: POINT(-58.379472895148915 -34.60132885666888)
A21: 45818.999 | B21: 0.99930556 | C21: csp_0020 | D21: https://maps.google.com/maps?q=-34.599891662597656%2C-58.37984848022461&z=17&hl=es | J21: Verduleria | O21: 1000 | V21: no | W21: si | X21: 1 | Y21: POINT(-58.37983241049086 -34.599679721329295)
A22: 45819 | B22: 0 | C22: csp_0021 | D22: https://maps.google.com/maps?q=-34.599876403808594%2C-58.379634857177734&z=17&hl=es | J22: Supermercado Dia | K22: 1390 | L22: 790 | M22: 990 | N22: 1600 | P22: 2145 | V22: si | W22: si | X22: 1 | Y22: POINT(-58.379683183503644 -34.599664421290306)
A23: 45819.003 | B23: 0.0027777778 | C23: csp_0022 | D23: https://maps.google.com/maps?q=-34.59871292114258%2C-58.37973403930664&z=17&hl=es | J23: Almacen | M23: 1500 | N23: 1800 | V23: no | W23: si | X23: 1 | Y23: POINT(-58.37975009699739 -34.59856273847909)
A24: 45819.003 | B24: 0.0034722222 | C24: csp_0023 | D24: https://maps.google.com/maps?q=-34.5986896%2C-58.3797565&z=17&hl=es | J24: Verduleria | O24: 800 | V24: no | W24: si | X24: 1 | Y24: POINT(-58.379740410490925 -34.59846878680459)
A25: 45819.005 | B25: 0.0048611111 | C25: csp_0024 | D25: https://maps.google.com/maps?q=-34.598295%2C-58.3797894&z=17&hl=es | J25: Almacen | L25: 2500 | N25: 2000 | V25: no | W25: si | X25: 1 | Y25: POINT(-58.379773310490876 -34.59810951174743)
A26: 45819.006 | B26: 0.0055555556 | C26: csp_0025 | D26: https://maps.google.com/maps?q=-34.5980989%2C-58.3797356&z=17&hl=es | J26: Almacen | M26: 1100 | N26: 1800 | O26: 700 | P26: 1200 | Q26: 14500 | V26: no | W26: si | X26: 1 | Y26: POINT(-58.3797624258329 -34.59795756888206)
A27: 45819.009 | B27: 0.0090277778 | C27: csp_0026 | D27: https://maps.google.com/maps?q=-34.5971262%2C-58.3798431&z=17&hl=es | J27: Almacen Chino | L27: 1500 | M27: 1700 | N27: 2000 | O27: 1200 | P27: 1500 | Q27: 900 | V27: no | W27: si | X27: 1 | Y27: POINT(-58.379805552819946 -34.59694954075799)
A28: 45820.735 | B28: 0.73541667 | C28: csp_0027 | D28: https://maps.google.com/maps?q=-34.59231185913086%2C-58.37621307373047&z=17&hl=es | J28: Almacen Chino | K28: 1600 | L28: 1000 | M28: 1500 | N28: 1800 | O28: 1000 | P28: 2300 | V28: no | W28: si | X28: 1 | Y28: POINT(-58.376207739326574 -34.592117566258686)
A29: 45820.746 | B29: 0.74583333 | C29: csp_0028 | D29: https://maps.google.com/maps?q=-34.58771896362305%2C-58.38430404663086&z=17&hl=es | J29: Almacen Chino | K29: 1400 | L29: 2000 | M29: 2000 | N29: 4000 | P29: 2136 | V29: no | W29: si | X29: 1 | Y29: POINT(-58.384298639326836 -34.587533488139755)
A30: 45820.751 | B30: 0.75069444 | C30: csp_0029 | D30: https://maps.google.com/maps?q=-34.586002349853516%2C-58.387351989746094&z=17&hl=es | J30: Verduleria | O30: 1333 | V30: no | W30: si | X30: 1 | Y30: POINT(-58.38738955466894 -34.58580795150509)
A31: 45820.751 | B31: 0.75138889 | C31: csp_0030 | D31: https://maps.google.com/maps?q=-34.585933685302734%2C-58.387969970703125&z=17&hl=es | J31: Supermercado Carrefour Express | K31: 1290 | L31: 749 | M31: 949 | N31: 1290 | O31: 1400 | P31: 1788 | Q31: 9350 | V31: si | W31: si | X31: 1 | Y31: POINT(-58.38795391049146 -34.585721685720785)
A32: 45820.76 | B32: 0.75972222 | C32: csp_0031 | D32: https://maps.google.com/maps?q=-34.5875244140625%2C-58.38737106323242&z=17&hl=es | J32: Kiosco Mini Market | K32: 2100 | L32: 1200 | M32: 2000 | N32: 5200 | U32: (U marca de cada producto, y pocos ejemplares por producto. muy poco provisto) | V32: no | W32: si | X32: 1 | Y32: POINT(-58.38743011233964 -34.58733888770553)
A33: 45820.77 | B33: 0.77013889 | C33: csp_0032 | D33: https://www.google.com/maps/@-34.5917245,-58.3792782,21z?hl=es&entry=ttu&g_ep=EgoyMDI2MDMxMS4wIKXMDSoASAFQAw%3D%3D | J33: Almacen | K33: 1485 | L33: 940 | M33: 949 | N33: 1400 | O33: 1400 | P33: 1288 | V33: no | W33: si | X33: 1 | Y33: POINT(-58.37935967209949 -34.59165991469645)
A34: 45820.774 | B34: 0.77361111 | C34: csp_0033 | D34: https://maps.google.com/maps?q=-34.59185791015625%2C-58.378448486328125&z=17&hl=es | J34: Supermercado Disco | K34: 1290 | L34: 870 | M34: 1080 | N34: 1050 | O34: 1629 | P34: 1845 | Q34: 5315 | V34: si | W34: si | X34: 1 | Y34: POINT(-58.3784753258331 -34.59167239737799)
A35: 45820.781 | B35: 0.78125 | C35: csp_0034 | D35: https://www.google.com/maps/@-34.5928267,-58.3763974,21z?hl=es&entry=ttu&g_ep=EgoyMDI2MDMxMS4wIKXMDSoASAFQAw%3D%3D | J35: Almacen | L35: 1000 | N35: 1400 | O35: 1500 | V35: no | W35: si | X35: 1 | Y35: POINT(-58.376197216356985 -34.5928172847864)
A36: 45820.787 | B36: 0.78680556 | C36: csp_0035 | D36: https://www.google.com/maps/@-34.5940337,-58.3793313,21z?hl=es&entry=ttu&g_ep=EgoyMDI2MDMxMS4wIKXMDSoASAFQAw%3D%3D | J36: Supermercado Jumbo | K36: 1950 | L36: 870 | M36: 1080 | N36: 1550 | O36: 969 | P36: 139 | Q36: 8855 | V36: si | W36: si | X36: 1 | Y36: POINT(-58.37937322983343 -34.5941396898721)
A37: 45820.792 | B37: 0.79236111 | C37: csp_0036 | D37: https://www.google.com/maps?q=-34.594242095947266,-58.38105392456055&z=17&hl=es | J37: Supermercado Carrefour Express | K37: 1290 | L37: 749 | M37: 949 | N37: 1290 | O37: 1590 | P37: 1788 | V37: si | W37: si | X37: 1 | Y37: POINT(-58.38104853932667 -34.59403893884416)
A38: 45820.795 | B38: 0.79513889 | C38: csp_0037 | D38: https://www.google.com/maps?q=-34.5941162109375,-58.37980270385742&z=17&hl=es | J38: Verduleria | O38: 1000 | V38: no | W38: si | X38: 1 | Y38: POINT(-58.37982952583306 -34.59393953435863)
A39: 45820.796 | B39: 0.79583333 | C39: csp_0038 | D39: https://www.google.com/maps?q=-34.59412384033203,-58.37968444824219&z=17&hl=es | J39: Carniceria RES | Q39: 545 | V39: si | W39: si | X39: 1 | Y39: POINT(-58.37971122583305 -34.59394713437477)
A40: 45820.797 | B40: 0.79722222 | C40: csp_0039 | D40: https://www.google.com/maps?q=-34.594486236572266,-58.381168365478516&z=17&hl=es | J40: Fiambreria | L40: 1400 | M40: 1200 | P40: 1500 | V40: no | W40: si | X40: 1 | Y40: POINT(-58.381227412339314 -34.59430070324479)
...

Sheet z_datos originales
A1: fecha_hora_cest | B1: marca_temp_CEST | C1: id_comercio | D1: link | E1: sector_bm | F1: Calle | G1: Altura | H1: direccion | I1: ID_direcciones | J1: Rubro | K1: leche | L1: harina | M1: azucar | N1: arroz | O1: papa | P1: fiambre/jc | Q1: carne pic | R1: ¿Cuáles son los principales factores que encarecen los productos que vendés? | S1: Inquilino/ Propietario | T1: Alquiler | U1: Dificultades para abastecerse, otros comentarios | V1: cadena | W1: relevado | X1: tanda | Y1: geometry | Z1: numero real
A2: 45818.953 | B2: 0.95277778 | C2: csp_0001 | D2: https://maps.google.com/maps?q=-34.59994888305664%2C-58.37699508666992&z=17&hl=es | J2: Supermercado Carrefour Express | K2: 1485 | L2: 749 | M2: 1050 | N2: 1690 | O2: 1490 | P2: 1790 | V2: si | W2: si | X2: 1 | Y2: POINT(-58.376946823984355 -34.599772246759564)
A3: 45818.955 | B3: 0.95486111 | C3: csp_0002 | D3: https://maps.google.com/maps?q=-34.59996032714844%2C-58.37679672241211&z=17&hl=es | J3: Carniceria RES | Q3: 5450 | V3: si | W3: si | X3: 1 | Y3: POINT(-58.37675915281983 -34.599783646783784)
A4: 45818.956 | B4: 0.95625 | C4: csp_0003 | D4: https://maps.google.com/maps?q=-34.599769592285156%2C-58.376834869384766&z=17&hl=es | J4: Almacen | N4: 1800 | O4: 750 | P4: 1500 | V4: no | W4: si | X4: 1 | Y4: POINT(-58.376872454668245 -34.59954878967517)
A5: 45818.958 | B5: 0.95833333 | C5: csp_0004 | D5: https://maps.google.com/maps?q=-34.598236083984375%2C-58.376956939697266&z=17&hl=es | J5: Almacen Chino | K5: 1300 | L5: 800 | M5: 900 | N5: 1400 | P5: 1200 | V5: no | W5: si | X5: 1 | Y5: POINT(-58.37690862398452 -34.59804178011319)
A6: 45818.96 | B6: 0.96041667 | C6: csp_0005 | D6: https://maps.google.com/maps?q=-34.59791946411133%2C-58.37689971923828&z=17&hl=es | J6: Carniceria Fiambreria | P6: 1950 | V6: si | W6: si | X6: 1 | Y6: POINT(-58.37691579699724 -34.597707516297156)
A7: 45818.961 | B7: 0.96111111 | C7: csp_0006 | D7: https://maps.google.com/maps?q=-34.59733581542969%2C-58.37691879272461&z=17&hl=es | J7: Supermercado Carrefour Express | K7: 1290 | L7: 749 | M7: 949 | N7: 1400 | O7: 1490 | P7: 1790 | V7: si | W7: si | X7: 1 | Y7: POINT(-58.37692416816192 -34.59711498320661)
A8: 45818.966 | B8: 0.96597222 | C8: csp_0007 | D8: https://maps.google.com/maps?q=-34.596309661865234%2C-58.37836837768555&z=17&hl=es | J8: Carniceria RES | Q8: 5450 | V8: si | W8: si | X8: 1 | Y8: POINT(-58.37833085282006 -34.59612420731531)
A9: 45818.967 | B9: 0.96666667 | C9: csp_0008 | D9: https://maps.google.com/maps?q=-34.59626770019531%2C-58.37843322753906&z=17&hl=es | J9: Almacen | K9: 2400 | L9: 1300 | M9: 1600 | N9: 2400 | P9: 1700 | V9: no | W9: si | X9: 1 | Y9: POINT(-58.37836346631361 -34.59609103893263)
A10: 45818.968 | B10: 0.96805556 | C10: csp_0009 | D10: https://maps.google.com/maps?q=-34.59589767456055%2C-58.37848663330078&z=17&hl=es | J10: Supermercado Carrefour Express | K10: 1290 | L10: 749 | M10: 899 | N10: 1290 | O10: 1490 | P10: 1785 | V10: si | W10: si | X10: 1 | Y10: POINT(-58.37839540864261 -34.59571220639564)
A11: 45818.974 | B11: 0.97430556 | C11: csp_0010 | D11: https://maps.google.com/maps?q=-34.5966682434082%2C-58.37837600708008&z=17&hl=es | J11: Almacen Chino | K11: 1800 | L11: 1500 | M11: 1300 | N11: 1000 | P11: 1000 | V11: no | W11: si | X11: 1 | Y11: POINT(-58.378327723984455 -34.596403223057045)
A12: 45818.976 | B12: 0.97638889 | C12: csp_0011 | D12: https://maps.google.com/maps?q=-34.59672546386719%2C-58.37849044799805&z=17&hl=es | J12: Verduleria | O12: 1000 | V12: no | W12: si | X12: 1 | Y12: POINT(-58.37844212398452 -34.59655767156747)
A13: 45818.978 | B13: 0.97777778 | C13: csp_0012 | D13: https://www.google.com/maps/place/34%C2%B035'50.5%22S+58%C2%B022'44.1%22W/@-34.5975982,-58.3788232,21z/data=!4m4!3m3!8m2!3d-34.5973587!4d-58.3789177?hl=es&entry=ttu&g_ep=EgoyMDI2MDMxMS4wIKXMDSoASAFQAw%3D%3D | J13: Almacen | L13: 1800 | M13: 2000 | P13: 1300 | V13: no | W13: si | X13: 1 | Y13: POINT(-58.37869881477214 -34.5976081096709)
A14: 45818.978 | B14: 0.97847222 | C14: csp_0013 | D14: https://maps.google.com/maps?q=-34.59750747680664%2C-58.3781852722168&z=17&hl=es | J14: Supermercado Dia | K14: 1740 | L14: 790 | M14: 990 | N14: 1190 | P14: 2410 | V14: si | W14: si | X14: 1 | Y14: POINT(-58.378201396997426 -34.597295515245946)
A15: 45818.981 | B15: 0.98125 | C15: csp_0014 | D15: https://maps.google.com/maps?q=-34.59797668457031%2C-58.378299713134766&z=17&hl=es | J15: Almacen | N15: 1800 | O15: 1000 | V15: no | W15: si | X15: 1 | Y15: POINT(-58.378272881655505 -34.59776471644315)
A16: 45818.983 | B16: 0.98263889 | C16: csp_0015 | D16: https://maps.google.com/maps?q=-34.598628997802734%2C-58.37840270996094&z=17&hl=es | J16: Supermercado Carrefour Express | K16: 1290 | L16: 749 | M16: 899 | N16: 1290 | O16: 1490 | P16: 1785 | V16: si | W16: si | X16: 1 | Y16: POINT(-58.3784617123392 -34.59848766978374)
A17: 45818.986 | B17: 0.98611111 | C17: csp_0016 | D17: https://maps.google.com/maps?q=-34.60411071777344%2C-58.3782844543457&z=17&hl=es | J17: Almacen | K17: 1900 | L17: 1300 | M17: 1400 | N17: 2600 | P17: 1035 | V17: no | W17: si | X17: 1 | Y17: POINT(-58.37825768165517 -34.603881070332164)
A18: 45818.99 | B18: 0.99027778 | C18: csp_0017 | D18: https://maps.google.com/maps?q=-34.60270690917969%2C-58.37809371948242&z=17&hl=es | J18: Fiambreria | N18: 2200 | O18: 900 | P18: 1742 | V18: no | W18: si | X18: 1 | Y18: POINT(-58.37807761049078 -34.60250375954193)
A19: 45818.991 | B19: 0.99097222 | C19: csp_0018 | D19: https://maps.google.com/maps?q=-34.60324478149414%2C-58.3781623840332&z=17&hl=es | J19: Supermercado Carrefour Express | K19: 1290 | L19: 749 | M19: 899 | N19: 1290 | O19: 1490 | P19: 1785 | V19: si | W19: si | X19: 1 | Y19: POINT(-58.378135581655215 -34.60302399891231)
A20: 45818.997 | B20: 0.99652778 | C20: csp_0019 | D20: https://maps.google.com/maps?q=-34.601531982421875%2C-58.37953186035156&z=17&hl=es | J20: Almacen Chino | K20: 1700 | L20: 900 | M20: 1300 | N20: 1200 | O20: 1000 | P20: 1600 | Q20: 8600 | V20: no | W20: si | X20: 1 | Y20: POINT(-58.379472895148915 -34.60132885666888)
A21: 45818.999 | B21: 0.99930556 | C21: csp_0020 | D21: https://maps.google.com/maps?q=-34.599891662597656%2C-58.37984848022461&z=17&hl=es | J21: Verduleria | O21: 1000 | V21: no | W21: si | X21: 1 | Y21: POINT(-58.37983241049086 -34.599679721329295)
A22: 45819 | B22: 0 | C22: csp_0021 | D22: https://maps.google.com/maps?q=-34.599876403808594%2C-58.379634857177734&z=17&hl=es | J22: Supermercado Dia | K22: 1390 | L22: 790 | M22: 990 | N22: 1600 | P22: 2145 | V22: si | W22: si | X22: 1 | Y22: POINT(-58.379683183503644 -34.599664421290306)
A23: 45819.003 | B23: 0.0027777778 | C23: csp_0022 | D23: https://maps.google.com/maps?q=-34.59871292114258%2C-58.37973403930664&z=17&hl=es | J23: Almacen | M23: 1500 | N23: 1800 | V23: no | W23: si | X23: 1 | Y23: POINT(-58.37975009699739 -34.59856273847909)
A24: 45819.003 | B24: 0.0034722222 | C24: csp_0023 | D24: https://maps.google.com/maps?q=-34.5986896%2C-58.3797565&z=17&hl=es | J24: Verduleria | O24: 800 | V24: no | W24: si | X24: 1 | Y24: POINT(-58.379740410490925 -34.59846878680459)
A25: 45819.005 | B25: 0.0048611111 | C25: csp_0024 | D25: https://maps.google.com/maps?q=-34.598295%2C-58.3797894&z=17&hl=es | J25: Almacen | L25: 2500 | N25: 2000 | V25: no | W25: si | X25: 1 | Y25: POINT(-58.379773310490876 -34.59810951174743)
A26: 45819.006 | B26: 0.0055555556 | C26: csp_0025 | D26: https://maps.google.com/maps?q=-34.5980989%2C-58.3797356&z=17&hl=es | J26: Almacen | M26: 1100 | N26: 1800 | O26: 700 | P26: 1200 | Q26: 14500 | V26: no | W26: si | X26: 1 | Y26: POINT(-58.3797624258329 -34.59795756888206)
A27: 45819.009 | B27: 0.0090277778 | C27: csp_0026 | D27: https://maps.google.com/maps?q=-34.5971262%2C-58.3798431&z=17&hl=es | J27: Almacen Chino | L27: 1500 | M27: 1700 | N27: 2000 | O27: 1200 | P27: 1500 | Q27: 900 | V27: no | W27: si | X27: 1 | Y27: POINT(-58.379805552819946 -34.59694954075799)
A28: 45820.735 | B28: 0.73541667 | C28: csp_0027 | D28: https://maps.google.com/maps?q=-34.59231185913086%2C-58.37621307373047&z=17&hl=es | J28: Almacen Chino | K28: 1600 | L28: 1000 | M28: 1500 | N28: 1800 | O28: 1000 | P28: 2300 | V28: no | W28: si | X28: 1 | Y28: POINT(-58.376207739326574 -34.592117566258686)
A29: 45820.746 | B29: 0.74583333 | C29: csp_0028 | D29: https://maps.google.com/maps?q=-34.58771896362305%2C-58.38430404663086&z=17&hl=es | J29: Almacen Chino | K29: 1400 | L29: 2000 | M29: 2000 | N29: 4000 | P29: 2136 | V29: no | W29: si | X29: 1 | Y29: POINT(-58.384298639326836 -34.587533488139755)
A30: 45820.751 | B30: 0.75069444 | C30: csp_0029 | D30: https://maps.google.com/maps?q=-34.586002349853516%2C-58.387351989746094&z=17&hl=es | J30: Verduleria | O30: 1333 | V30: no | W30: si | X30: 1 | Y30: POINT(-58.38738955466894 -34.58580795150509)
A31: 45820.751 | B31: 0.75138889 | C31: csp_0030 | D31: https://maps.google.com/maps?q=-34.585933685302734%2C-58.387969970703125&z=17&hl=es | J31: Supermercado Carrefour Express | K31: 1290 | L31: 749 | M31: 949 | N31: 1290 | O31: 1400 | P31: 1788 | Q31: 9350 | V31: si | W31: si | X31: 1 | Y31: POINT(-58.38795391049146 -34.585721685720785)
A32: 45820.76 | B32: 0.75972222 | C32: csp_0031 | D32: https://maps.google.com/maps?q=-34.5875244140625%2C-58.38737106323242&z=17&hl=es | J32: Kiosco Mini Market | K32: 2100 | L32: 1200 | M32: 2000 | N32: 5200 | U32: (U marca de cada producto, y pocos ejemplares por producto. muy poco provisto) | V32: no | W32: si | X32: 1 | Y32: POINT(-58.38743011233964 -34.58733888770553)
A33: 45820.77 | B33: 0.77013889 | C33: csp_0032 | D33: https://www.google.com/maps/@-34.5917245,-58.3792782,21z?hl=es&entry=ttu&g_ep=EgoyMDI2MDMxMS4wIKXMDSoASAFQAw%3D%3D | J33: Almacen | K33: 1485 | L33: 940 | M33: 949 | N33: 1400 | O33: 1400 | P33: 1288 | V33: no | W33: si | X33: 1 | Y33: POINT(-58.37935967209949 -34.59165991469645)
A34: 45820.774 | B34: 0.77361111 | C34: csp_0033 | D34: https://maps.google.com/maps?q=-34.59185791015625%2C-58.378448486328125&z=17&hl=es | J34: Supermercado Disco | K34: 1290 | L34: 870 | M34: 1080 | N34: 1050 | O34: 1629 | P34: 1845 | Q34: 5315 | V34: si | W34: si | X34: 1 | Y34: POINT(-58.3784753258331 -34.59167239737799)
A35: 45820.781 | B35: 0.78125 | C35: csp_0034 | D35: https://www.google.com/maps/@-34.5928267,-58.3763974,21z?hl=es&entry=ttu&g_ep=EgoyMDI2MDMxMS4wIKXMDSoASAFQAw%3D%3D | J35: Almacen | L35: 1000 | N35: 1400 | O35: 1500 | V35: no | W35: si | X35: 1 | Y35: POINT(-58.376197216356985 -34.5928172847864)
A36: 45820.787 | B36: 0.78680556 | C36: csp_0035 | D36: https://www.google.com/maps/@-34.5940337,-58.3793313,21z?hl=es&entry=ttu&g_ep=EgoyMDI2MDMxMS4wIKXMDSoASAFQAw%3D%3D | J36: Supermercado Jumbo | K36: 1950 | L36: 870 | M36: 1080 | N36: 1550 | O36: 969 | P36: 139 | Q36: 8855 | V36: si | W36: si | X36: 1 | Y36: POINT(-58.37937322983343 -34.5941396898721)
A37: 45820.792 | B37: 0.79236111 | C37: csp_0036 | D37: https://www.google.com/maps?q=-34.594242095947266,-58.38105392456055&z=17&hl=es | J37: Supermercado Carrefour Express | K37: 1290 | L37: 749 | M37: 949 | N37: 1290 | O37: 1590 | P37: 1788 | V37: si | W37: si | X37: 1 | Y37: POINT(-58.38104853932667 -34.59403893884416)
A38: 45820.795 | B38: 0.79513889 | C38: csp_0037 | D38: https://www.google.com/maps?q=-34.5941162109375,-58.37980270385742&z=17&hl=es | J38: Verduleria | O38: 1000 | V38: no | W38: si | X38: 1 | Y38: POINT(-58.37982952583306 -34.59393953435863)
A39: 45820.796 | B39: 0.79583333 | C39: csp_0038 | D39: https://www.google.com/maps?q=-34.59412384033203,-58.37968444824219&z=17&hl=es | J39: Carniceria RES | Q39: 545 | V39: si | W39: si | X39: 1 | Y39: POINT(-58.37971122583305 -34.59394713437477)
A40: 45820.797 | B40: 0.79722222 | C40: csp_0039 | D40: https://www.google.com/maps?q=-34.594486236572266,-58.381168365478516&z=17&hl=es | J40: Fiambreria | L40: 1400 | M40: 1200 | P40: 1500 | V40: no | W40: si | X40: 1 | Y40: POINT(-58.381227412339314 -34.59430070324479)
...

Sheet solapados_tanda1y2
A1: fecha_hora_cest | B1: marca_temp_CEST | C1: id_comercio | D1: link | E1: sector_bm | F1: Calle | G1: Altura | H1: direccion | I1: ID_direcciones | J1: Rubro | K1: leche | L1: harina | M1: azucar | N1: arroz | O1: papa | P1: fiambre/jc | Q1: carne pic | R1: ¿Cuáles son los principales factores que encarecen los productos que vendés? | S1: Inquilino/ Propietario | T1: Alquiler | U1: Dificultades para abastecerse, otros comentarios | V1: cadena | W1: relevado | X1: tanda | Y1: geometry | Z1: numero real
A2: 45820.751 | B2: 0.75069444 | C2: csp_0029 | D2: https://maps.google.com/maps?q=-34.586002349853516%2C-58.387351989746094&z=17&hl=es | J2: Verduleria | O2: 1333 | V2: no | W2: si | X2: 1 | Y2: POINT(-58.38738955466894 -34.58580795150509)
A3: 46002 | B3: 0.80138889 | C3: csp_0097 | D3: https://www.google.com/maps?q=-34.5859489440918,-58.38724136352539&z=17&hl=es | J3: Verduleria | O3: 2000 | V3: no | W3: si | X3: 2 | Y3: POINT(-58.387241 -34.585949)
O4: =O2/O3 -> 0.6665
A5: 45820.746 | B5: 0.74583333 | C5: csp_0028 | D5: https://maps.google.com/maps?q=-34.58771896362305%2C-58.38430404663086&z=17&hl=es | J5: Almacen Chino | K5: 1400 | L5: 2000 | M5: 2000 | N5: 4000 | P5: 2136 | V5: no | W5: si | X5: 1 | Y5: POINT(-58.384298639326836 -34.587533488139755)
A6: 46002 | B6: 0.77638889 | C6: csp_0091 | D6: https://www.google.com/maps?q=-34.58757019042969,-58.38422775268555&z=17&hl=es | J6: Almacen Chino | K6: 2300 | L6: 2300 | M6: 2000 | N6: 5000 | P6: =23000/10 -> 2300 | V6: no | W6: si | X6: 2 | Y6: POINT(-58.384228 -34.587570)
K7: =K5/K6 -> 0.60869565 | L7: =L5/L6 -> 0.86956522 | M7: =M5/M6 -> 1 | N7: =N5/N6 -> 0.8 | P7: =P5/P6 -> 0.92869565
A8: 45820.912 | B8: 0.9125 | C8: csp_0070 | D8: https://www.google.com/maps?q=-34.59014892578125,-58.388126373291016&z=17&hl=es | J8: Fiambreria | P8: 725 | V8: no | W8: si | X8: 1 | Y8: POINT(-58.38813176816218 -34.589919231741334)
A9: 46002 | B9: 0.78472222 | C9: csp_0093 | D9: https://www.google.com/maps?q=-34.59028244018555,-58.388267517089844&z=17&hl=es | J9: Fiambreria | P9: =1500/2 -> 750 | V9: no | W9: si | X9: 2 | Y9: POINT(-58.388268 -34.590282)
P10: =P8/P9 -> 0.96666667
A11: 45820.76 | B11: 0.75972222 | C11: csp_0031 | D11: https://maps.google.com/maps?q=-34.5875244140625%2C-58.38737106323242&z=17&hl=es | J11: Kiosco Mini Market | K11: 2100 | L11: 1200 | M11: 2000 | N11: 5200 | U11: (U marca de cada producto, y pocos ejemplares por producto. muy poco provisto) | V11: no | W11: si | X11: 1 | Y11: POINT(-58.38743011233964 -34.58733888770553)
A12: 46002 | B12: 0.75 | C12: csp_0088 | D12: https://www.google.com/maps?q=-34.58756637573242,-58.38724136352539&z=17&hl=es | J12: Almacen | K12: 2900 | L12: 1300 | M12: 2000 | N12: 5200 | V12: no | W12: si | X12: 2 | Y12: POINT(-58.387241 -34.587566)
K13: =K11/K12 -> 0.72413793 | L13: =L11/L12 -> 0.92307692 | M13: =M11/M12 -> 1 | N13: =N11/N12 -> 1
A14: 45820.91 | B14: 0.91041667 | C14: csp_0069 | D14: https://www.google.com/maps?q=-34.591373443603516,-58.389549255371094&z=17&hl=es | J14: Carniceria RES | Q14: 5450 | V14: si | W14: si | X14: 1 | Y14: POINT(-58.38958685466864 -34.59115256736145)
A15: 46002 | B15: 0.78680556 | C15: csp_0094 | D15: https://www.google.com/maps?q=-34.59125518798828,-58.3893928527832&z=17&hl=es | J15: Carniceria RES | Q15: 13900 | V15: si | W15: si | X15: 2 | Y15: POINT(-58.389393 -34.591255)
Q16: =Q14/Q15 -> 0.39208633
A17: 45820.923 | B17: 0.92291667 | C17: csp_0071 | D17: https://www.google.com/maps?q=-34.592044830322266,-58.39152145385742&z=17&hl=es | J17: Almacen | K17: 1600 | L17: 1381 | M17: 1350 | N17: 1400 | P17: 1399 | V17: no | W17: si | X17: 1 | Y17: POINT(-58.39152686816208 -34.59187696211415)
A18: 46002 | B18: 0.71527778 | C18: csp_0082 | D18: https://www.google.com/maps?q=-34.59210205078125,-58.39177703857422&z=17&hl=es | J18: Almacen Chino | K18: 1600 | L18: 1050 | M18: 1550 | N18: 1600 | P18: =14000/10 -> 1400 | V18: no | W18: si | X18: 2 | Y18: POINT(-58.391777 -34.592102)
K19: =K17/K18 -> 1 | L19: =L17/L18 -> 1.3152381 | M19: =M17/M18 -> 0.87096774 | N19: =N17/N18 -> 0.875 | P19: =P17/P18 -> 0.99928571
A20: 45820.926 | B20: 0.92569444 | C20: csp_0072 | D20: https://www.google.com/maps?q=-34.59115219116211,-58.39268493652344&z=17&hl=es | J20: Verduleria | O20: 725 | V20: no | W20: si | X20: 1 | Y20: POINT(-58.39263662398475 -34.59092253451398)
A21: 46002 | B21: 0.71319444 | C21: csp_0081 | D21: https://www.google.com/maps?q=-34.59121322631836,-58.39257049560547&z=17&hl=es | J21: Verduleria | O21: =1500/2 -> 750 | V21: no | W21: si | X21: 2 | Y21: POINT(-58.392571 -34.591213)
O22: =O20/O21 -> 0.96666667
A23: 45820.926 | B23: 0.92638889 | C23: csp_0073 | D23: https://www.google.com/maps?q=-34.59111022949219,-58.39280319213867&z=17&hl=es | J23: Verduleria | O23: 725 | V23: no | W23: si | X23: 1 | Y23: POINT(-58.39287294117505 -34.590880534397805)
A24: 46002 | B24: 0.71180556 | C24: csp_0080 | D24: https://www.google.com/maps?q=-34.59075164794922,-58.39310073852539&z=17&hl=es | J24: Verduleria | O24: 1000 | V24: no | W24: si | X24: 2 | Y24: POINT(-58.393101 -34.590752)
O25: =O23/O24 -> 0.725
A26: 45820.847 | B26: 0.84652778 | C26: csp_0046 | D26: https://www.google.com/maps?q=-34.592796325683594,-58.385894775390625&z=17&hl=es | J26: Verduleria | O26: 900 | V26: no | W26: si | X26: 1 | Y26: POINT(-58.38591089699757 -34.59260196739151)
A27: 46002 | B27: 0.84375 | C27: csp_0104 | D27: https://www.google.com/maps?q=-34.59281921386719,-58.38582229614258&z=17&hl=es | J27: Verduleria | O27: 1500 | V27: no | W27: si | X27: 2 | Y27: POINT(-58.385822 -34.592819)
A38: ELIMINAR 1005 Y 1006
L39: MEDIANA 12/06/25 A 11/12/25 | P39: =MEDIAN(Q39:Q57) -> 0.92307692 | Q39: =O4 -> 0.6665
Q40: {=TRANSPOSE(K7:N7)} -> 0.60869565
Q41: 0.86956522
Q42: 1
Q43: 0.8
Q44: =P7 -> 0.92869565
Q45: =P10 -> 0.96666667
Q46: {=TRANSPOSE(K13:N13)} -> 0.72413793
Q47: 0.92307692
Q48: 1
Q49: 1
Q50: =Q16 -> 0.39208633
...

Sheet Hoja3
A1: POINT(-58.394901 -34.589634)
A2: POINT(-58.394527 -34.589733)
A3: -34.589943, -58.394119 | B3: =CONCATENATE("POINT(",RIGHT(A3,10), " ",LEFT(A3,10),")") -> POINT(-58.394119 -34.589943)
A4: -34.590313, -58.393669 | B4: =CONCATENATE("POINT(",RIGHT(A4,10), " ",LEFT(A4,10),")") -> POINT(-58.393669 -34.590313)
A5: -34.590752, -58.393101 | B5: =CONCATENATE("POINT(",RIGHT(A5,10), " ",LEFT(A5,10),")") -> POINT(-58.393101 -34.590752)
A6: -34.591213, -58.392571 | B6: =CONCATENATE("POINT(",RIGHT(A6,10), " ",LEFT(A6,10),")") -> POINT(-58.392571 -34.591213)
A7: -34.592102, -58.391777 | B7: =CONCATENATE("POINT(",RIGHT(A7,10), " ",LEFT(A7,10),")") -> POINT(-58.391777 -34.592102)
A8: -34.592506, -58.391026 | B8: =CONCATENATE("POINT(",RIGHT(A8,10), " ",LEFT(A8,10),")") -> POINT(-58.391026 -34.592506)
A9: -34.590828, -58.392952 | B9: =CONCATENATE("POINT(",RIGHT(A9,10), " ",LEFT(A9,10),")") -> POINT(-58.392952 -34.590828)
A10: -34.591076, -58.390587 | B10: =CONCATENATE("POINT(",RIGHT(A10,10), " ",LEFT(A10,10),")") -> POINT(-58.390587 -34.591076)
A11: -34.591259, -58.390484 | B11: =CONCATENATE("POINT(",RIGHT(A11,10), " ",LEFT(A11,10),")") -> POINT(-58.390484 -34.591259)
A12: -34.591938, -58.389732 | B12: =CONCATENATE("POINT(",RIGHT(A12,10), " ",LEFT(A12,10),")") -> POINT(-58.389732 -34.591938)
A13: -34.587566, -58.387241 | B13: =CONCATENATE("POINT(",RIGHT(A13,10), " ",LEFT(A13,10),")") -> POINT(-58.387241 -34.587566)
A14: -34.591892, -58.384201 | B14: =CONCATENATE("POINT(",RIGHT(A14,10), " ",LEFT(A14,10),")") -> POINT(-58.384201 -34.591892)
... A31: -34.588848, -58.383034 | B31: =CONCATENATE("POINT(",RIGHT(A31,10), " ",LEFT(A31,10),")") -> POINT(-58.383034 -34.588848)

Sheet Hoja2
A1: {=_xlfn.UNIQUE(limpieza_datos!J2:J76)} -> Supermercado Carrefour Express
A2: Carniceria RES
A3: Almacen
A4: Almacen Chino
A5: Carniceria Fiambreria
A6: Verduleria
A7: Supermercado Dia
A8: Fiambreria
A9: Kiosco Mini Market
A10: Supermercado Disco
A11: Supermercado Jumbo
A12: Supermercado Carrefour Market
A13: Carniceria
